Workbook

Sheet Test_Methylation
A1: Properties | B1: Sequence | C1: Label | D1: MusiteDeep | G1: Tp | H1: FP | I1: TN | J1: FN | L1: SEN | M1: SPE | N1: BA | O1: ACC | P1: MCC | Q1: precision | R1: recall | S1: f1-score
A2: TRA2B_HUMAN_210 | B2: HTPTPGIYMGRPTYGSSRRRD | C2: 1 | D2: =VLOOKUP(A2,'MusiteDeep-11'!$A$1:$F$5115,6,0) -> #N/A | F2: MusiteDeep | G2: =COUNTIF($D$2:$D$2939,1) -> 2 | H2: =H5-I2 -> 3656 | I2: =COUNTIF($D$2940:$D$10240,0) -> 3645 | J2: =H4-G2 -> 2936 | K2: MusiteDeep | L2: =G2/(G2+J2) -> 0.00068073519 | M2: =I2/(I2+H2) -> 0.49924668 | N2: =(L2+M2)/2 -> 0.24996371 | O2: =SUM(G2,I2)/SUM(G2:J2) -> 0.35618713 | P2: =((G2*I2)-(H2*J2))/SQRT((G2+H2)*(G2+J2)*(I2+H2)*(I2+J2)) -> -0.47204383 | Q2: =G2/(G2+H2) -> 0.00054674686 | R2: =G2/(G2+J2) -> 0.00068073519 | S2: =2*(Q2*R2/(Q2+R2)) -> 0.00060642814
A3: NPB_MOUSE_52 | B3: SSFHRFPSTRRSESPALRVGT | C3: 1 | D3: =VLOOKUP(A3,'MusiteDeep-11'!$A$1:$F$5115,6,0) -> #N/A
A4: TULP4_HUMAN_1006 | B4: LKMAQLADSPRAPLQPLAKSK | C4: 1 | D4: =VLOOKUP(A4,'MusiteDeep-11'!$A$1:$F$5115,6,0) -> #N/A | G4: Positive | H4: =COUNTIF($C$2:$C$2939,1) -> 2938
A5: ZN462_HUMAN_2062 | B5: KPFRCKLCSFKSSYNSRLKTH | C5: 1 | D5: =VLOOKUP(A5,'MusiteDeep-11'!$A$1:$F$5115,6,0) -> 1 | G5: Negative | H5: =COUNTIF($C$2940:$C$10240,0) -> 7301
A6: F0NDF7_SULIR_127 | B6: EWFETLARAEKSHAEKFTAVL | C6: 1 | D6: =VLOOKUP(A6,'MusiteDeep-11'!$A$1:$F$5115,6,0) -> 0
A7: Q69ZY3_MOUSE_921 | B7: GPPGPVGTPLRFEGPIGQGGG | C7: 1 | D7: =VLOOKUP(A7,'MusiteDeep-11'!$A$1:$F$5115,6,0) -> #N/A
A8: SNX4_HUMAN_205 | B8: GFQLKADSRLKALNATFRVKN | C8: 1 | D8: =VLOOKUP(A8,'MusiteDeep-11'!$A$1:$F$5115,6,0) -> 0
A9: STRBP_HUMAN_617 | B9: VRGRGRGTLTRGAFVGATAAP | C9: 1 | D9: =VLOOKUP(A9,'MusiteDeep-11'!$A$1:$F$5115,6,0) -> #N/A
A10: VP13C_HUMAN_3553 | B10: AKKEGAAGFFKGIGKGLVGAV | C10: 1 | D10: =VLOOKUP(A10,'MusiteDeep-11'!$A$1:$F$5115,6,0) -> 0
A11: IQGA1_HUMAN_336 | B11: RALQSPALGLRGLQQQNSDWY | C11: 1 | D11: =VLOOKUP(A11,'MusiteDeep-11'!$A$1:$F$5115,6,0) -> #N/A
A12: F0NC29_SULIR_406 | B12: PLIIEEDLALKGTRILIEEIE | C12: 1 | D12: =VLOOKUP(A12,'MusiteDeep-11'!$A$1:$F$5115,6,0) -> 0
A13: HNRPQ_HUMAN_533 | B13: YSQRGGPGSARGVRGARGGAQ | C13: 1 | D13: =VLOOKUP(A13,'MusiteDeep-11'!$A$1:$F$5115,6,0) -> #N/A
A14: MYH4_HUMAN_1030 | B14: KVNTLTKAKTKLEQQVDDLEG | C14: 1 | D14: =VLOOKUP(A14,'MusiteDeep-11'!$A$1:$F$5115,6,0) -> 0
A15: TTC36_MOUSE_115 | B15: LERAVTLSGGRGRAARQSFVQ | C15: 1 | D15: =VLOOKUP(A15,'MusiteDeep-11'!$A$1:$F$5115,6,0) -> #N/A
A16: F0NCT2_SULIR_188 | B16: YRGEKDAEEIKNTLQKIKGGT | C16: 1 | D16: =VLOOKUP(A16,'MusiteDeep-11'!$A$1:$F$5115,6,0) -> 0
A17: SPTN1_HUMAN_1138 | B17: VLQKKFDDFQKDLKANESRLK | C17: 1 | D17: =VLOOKUP(A17,'MusiteDeep-11'!$A$1:$F$5115,6,0) -> 0
... A10240: LRP12_HUMAN_81 | B10240: PAKINCSWFIRANPGEIITIS | C10240: 0 | D10240: =VLOOKUP(A10240,'MusiteDeep-11'!$A$1:$F$5115,6,0) -> #N/A

Sheet musiteDeep
A1: ID | B1: Position | C1: Residue | D1: PTMscores | E1: Cutoff=0.5
A2: >TRA2B_HUMAN_210
A3: >NPB_MOUSE_52
A4: >TULP4_HUMAN_1006
A5: TULP4_HUMAN_1006 | B5: 2 | C5: K | D5: Methyllysine:0.819 | E5: Methyllysine:0.819
A6: TULP4_HUMAN_1006 | B6: 19 | C6: K | D6: Methyllysine:0.233 | E6: None
A7: TULP4_HUMAN_1006 | B7: 21 | C7: K | D7: Methyllysine:0.283 | E7: None
A8: >ZN462_HUMAN_2062
A9: ZN462_HUMAN_2062 | B9: 1 | C9: K | D9: Methyllysine:0.551 | E9: Methyllysine:0.551
A10: ZN462_HUMAN_2062 | B10: 6 | C10: K | D10: Methyllysine:0.441 | E10: None
A11: ZN462_HUMAN_2062 | B11: 11 | C11: K | D11: Methyllysine:0.552 | E11: Methyllysine:0.552
A12: ZN462_HUMAN_2062 | B12: 19 | C12: K | D12: Methyllysine:0.192 | E12: None
A13: >F0NDF7_SULIR_127
A14: F0NDF7_SULIR_127 | B14: 11 | C14: K | D14: Methyllysine:0.33 | E14: None
A15: F0NDF7_SULIR_127 | B15: 16 | C15: K | D15: Methyllysine:0.128 | E15: None
A16: >Q69ZY3_MOUSE_921
A17: >SNX4_HUMAN_205
A18: SNX4_HUMAN_205 | B18: 5 | C18: K | D18: Methyllysine:0.701 | E18: Methyllysine:0.701
A19: SNX4_HUMAN_205 | B19: 11 | C19: K | D19: Methyllysine:0.437 | E19: None
A20: SNX4_HUMAN_205 | B20: 20 | C20: K | D20: Methyllysine:0.229 | E20: None
A21: >STRBP_HUMAN_617
A22: >VP13C_HUMAN_3553
A23: VP13C_HUMAN_3553 | B23: 2 | C23: K | D23: Methyllysine:0.692 | E23: Methyllysine:0.692
A24: VP13C_HUMAN_3553 | B24: 3 | C24: K | D24: Methyllysine:0.851 | E24: Methyllysine:0.851
A25: VP13C_HUMAN_3553 | B25: 11 | C25: K | D25: Methyllysine:0.381 | E25: None
A26: VP13C_HUMAN_3553 | B26: 15 | C26: K | D26: Methyllysine:0.203 | E26: None
A27: >IQGA1_HUMAN_336
A28: >F0NC29_SULIR_406
A29: F0NC29_SULIR_406 | B29: 11 | C29: K | D29: Methyllysine:0.284 | E29: None
A30: >HNRPQ_HUMAN_533
A31: >MYH4_HUMAN_1030
A32: MYH4_HUMAN_1030 | B32: 1 | C32: K | D32: Methyllysine:0.61 | E32: Methyllysine:0.61
A33: MYH4_HUMAN_1030 | B33: 7 | C33: K | D33: Methyllysine:0.143 | E33: None
A34: MYH4_HUMAN_1030 | B34: 9 | C34: K | D34: Methyllysine:0.098 | E34: None
A35: MYH4_HUMAN_1030 | B35: 11 | C35: K | D35: Methyllysine:0.102 | E35: None
A36: >TTC36_MOUSE_115
A37: >F0NCT2_SULIR_188
A38: F0NCT2_SULIR_188 | B38: 5 | C38: K | D38: Methyllysine:0.572 | E38: Methyllysine:0.572
A39: F0NCT2_SULIR_188 | B39: 11 | C39: K | D39: Methyllysine:0.101 | E39: None
A40: F0NCT2_SULIR_188 | B40: 16 | C40: K | D40: Methyllysine:0.175 | E40: None
...

Sheet MusiteDeep-11
A1: ID | B1: Position | C1: Residue | D1: PTMscores | E1: Cutoff=0.5 | F1: pred
A2: ZN462_HUMAN_2062 | B2: 11 | C2: K | D2: Methyllysine:0.552 | E2: Methyllysine:0.552 | F2: =IF(E2=$E$2,1,0) -> 1
A3: F0NDF7_SULIR_127 | B3: 11 | C3: K | D3: Methyllysine:0.33 | E3: None | F3: =IF(E3=$E$2,1,0) -> 0
A4: SNX4_HUMAN_205 | B4: 11 | C4: K | D4: Methyllysine:0.437 | E4: None | F4: =IF(E4=$E$2,1,0) -> 0
A5: VP13C_HUMAN_3553 | B5: 11 | C5: K | D5: Methyllysine:0.381 | E5: None | F5: =IF(E5=$E$2,1,0) -> 0
A6: F0NC29_SULIR_406 | B6: 11 | C6: K | D6: Methyllysine:0.284 | E6: None | F6: =IF(E6=$E$2,1,0) -> 0
A7: MYH4_HUMAN_1030 | B7: 11 | C7: K | D7: Methyllysine:0.102 | E7: None | F7: =IF(E7=$E$2,1,0) -> 0
A8: F0NCT2_SULIR_188 | B8: 11 | C8: K | D8: Methyllysine:0.101 | E8: None | F8: =IF(E8=$E$2,1,0) -> 0
A9: SPTN1_HUMAN_1138 | B9: 11 | C9: K | D9: Methyllysine:0.166 | E9: None | F9: =IF(E9=$E$2,1,0) -> 0
A10: SUV92_HUMAN_85 | B10: 11 | C10: K | D10: Methyllysine:0.194 | E10: None | F10: =IF(E10=$E$2,1,0) -> 0
A11: F0NCM2_SULIR_201 | B11: 11 | C11: K | D11: Methyllysine:0.258 | E11: None | F11: =IF(E11=$E$2,1,0) -> 0
A12: Q72BN3_DESVH_718 | B12: 11 | C12: K | D12: Methyllysine:0.325 | E12: None | F12: =IF(E12=$E$2,1,0) -> 0
A13: RPA49_HUMAN_142 | B13: 11 | C13: K | D13: Methyllysine:0.201 | E13: None | F13: =IF(E13=$E$2,1,0) -> 0
... A5115: K0556_HUMAN_1501 | B5115: 11 | C5115: K | D5115: Methyllysine:0.265 | E5115: None | F5115: =IF(E5115=$E$2,1,0) -> 0
