Workbook

Sheet Test_Hydroxylation
A1: Properties | B1: Sequence | C1: Label | D1: MusiteDeep | H1: Tp | I1: FP | J1: TN | K1: FN | L1: SEN | M1: SPE | N1: BA | O1: ACC | P1: MCC | Q1: precision | R1: recall | S1: f1-score
A2: FP1V1_PERVI_352 | B2: TPKPWTAWKVPPPAWTAWKAH | C2: 1 | D2: =VLOOKUP(A2,'MusiteDeep-11'!$A$1:$F$124,6,0) -> #N/A | G2: MusiteDeep | H2: =COUNTIF($D$2:$D$255,1) -> 26 | I2: =I5-J2 -> 494 | J2: =COUNTIF($D$256:$D$835,0) -> 86 | K2: =I4-H2 -> 228 | L2: =H2/(H2+K2) -> 0.1023622 | M2: =J2/(J2+I2) -> 0.14827586 | N2: =(L2+M2)/2 -> 0.12531903 | O2: =SUM(H2,J2)/SUM(H2:K2) -> 0.13429257 | P2: =((H2*J2)-(I2*K2))/SQRT((H2+I2)*(H2+K2)*(J2+I2)*(J2+K2)) -> -0.71179673 | Q2: =H2/(H2+I2) -> 0.05 | R2: =H2/(H2+K2) -> 0.1023622 | S2: =2*(Q2*R2/(Q2+R2)) -> 0.067183463
A3: CAFF_RIFPA_164 | B3: GVDGLAGPPGPPGPIGSTGSP | C3: 1 | D3: =VLOOKUP(A3,'MusiteDeep-11'!$A$1:$F$124,6,0) -> #N/A
A4: CO2A1_BOVIN_218 | B4: PRGPPGPAGAPGPQGFQGNPG | C4: 1 | D4: =VLOOKUP(A4,'MusiteDeep-11'!$A$1:$F$124,6,0) -> #N/A | H4: Positive | I4: =COUNTIF($C$2:$C$255,1) -> 254
A5: CO17A_CONPU_49 | B5: KLSLSTRCRIPNQKCFQHLDD | C5: 1 | D5: =VLOOKUP(A5,'MusiteDeep-11'!$A$1:$F$124,6,0) -> #N/A | H5: Negative | I5: =COUNTIF($C$256:$C$835,0) -> 580
A6: H14_HUMAN_97 | B6: LVSKGTLVQTKGTGASGSFKL | C6: 1 | D6: =VLOOKUP(A6,'MusiteDeep-11'!$A$1:$F$124,6,0) -> 0
A7: CAFF_RIFPA_561 | B7: PPGPAGLVGLPGERGPKGVGG | C7: 1 | D7: =VLOOKUP(A7,'MusiteDeep-11'!$A$1:$F$124,6,0) -> #N/A
A8: CHI2_TOBAC_67 | B8: GNCQSQCPGGPTPPGGGDLGS | C8: 1 | D8: =VLOOKUP(A8,'MusiteDeep-11'!$A$1:$F$124,6,0) -> #N/A
A9: CO2A1_BOVIN_212 | B9: PMGPMGPRGPPGPAGAPGPQG | C9: 1 | D9: =VLOOKUP(A9,'MusiteDeep-11'!$A$1:$F$124,6,0) -> #N/A
A10: PRP_PHAVU_11 | B10: NYDKPPVEKPPVYKPPVEKPP | C10: 1 | D10: =VLOOKUP(A10,'MusiteDeep-11'!$A$1:$F$124,6,0) -> #N/A
A11: HSY1_SOLLC_63 | B11: KTPPPPTSSSPTHQEIVNGRH | C11: 1 | D11: =VLOOKUP(A11,'MusiteDeep-11'!$A$1:$F$124,6,0) -> #N/A
A12: RL27A_HUMAN_39 | B12: PGGRGNAGGLHHHRINFDKYH | C12: 1 | D12: =VLOOKUP(A12,'MusiteDeep-11'!$A$1:$F$124,6,0) -> #N/A
A13: PCEP9_ARATH_48 | B13: FKAGFTDDFVPTSPGNSPGVG | C13: 1 | D13: =VLOOKUP(A13,'MusiteDeep-11'!$A$1:$F$124,6,0) -> #N/A
A14: CO5A2_HUMAN_919 | B14: GFPGSAGRVGPPGPAGAPGPA | C14: 1 | D14: =VLOOKUP(A14,'MusiteDeep-11'!$A$1:$F$124,6,0) -> #N/A
A15: FP1V1_PERVI_27 | B15: SASAVYHPPSWTAWIAPKPWT | C15: 1 | D15: =VLOOKUP(A15,'MusiteDeep-11'!$A$1:$F$124,6,0) -> #N/A
A16: C1QB_HUMAN_86 | B16: EKGDPGIPGNPGKVGPKGPMG | C16: 1 | D16: =VLOOKUP(A16,'MusiteDeep-11'!$A$1:$F$124,6,0) -> #N/A
A17: AGP4_ARATH_37 | B17: TPTATPPPATPPPVATPPPVA | C17: 1 | D17: =VLOOKUP(A17,'MusiteDeep-11'!$A$1:$F$124,6,0) -> #N/A
... A835: ENAM_PIG_639 | B835: NPHYPMNTPDPKETIPYNEED | C835: 0 | D835: =VLOOKUP(A835,'MusiteDeep-11'!$A$1:$F$124,6,0) -> #N/A

Sheet MusiteDeep
A1: ID | B1: Position | C1: Residue | D1: PTMscores | E1: Cutoff=0.5
A2: FP1V1_PERVI_352 | B2: 3 | C2: K | D2: Hydroxylysine:0.043 | E2: None
A3: FP1V1_PERVI_352 | B3: 9 | C3: K | D3: Hydroxylysine:0.076 | E3: None
A4: FP1V1_PERVI_352 | B4: 19 | C4: K | D4: Hydroxylysine:0.11 | E4: None
A5: CO17A_CONPU_49 | B5: 1 | C5: K | D5: Hydroxylysine:0.051 | E5: None
A6: CO17A_CONPU_49 | B6: 14 | C6: K | D6: Hydroxylysine:0.052 | E6: None
A7: H14_HUMAN_97 | B7: 4 | C7: K | D7: Hydroxylysine:0.053 | E7: None
A8: H14_HUMAN_97 | B8: 11 | C8: K | D8: Hydroxylysine:0.227 | E8: None
A9: H14_HUMAN_97 | B9: 20 | C9: K | D9: Hydroxylysine:0.097 | E9: None
A10: CAFF_RIFPA_561 | B10: 17 | C10: K | D10: Hydroxylysine:0.644 | E10: Hydroxylysine:0.644
A11: PRP_PHAVU_11 | B11: 4 | C11: K | D11: Hydroxylysine:0.05 | E11: None
A12: PRP_PHAVU_11 | B12: 9 | C12: K | D12: Hydroxylysine:0.116 | E12: None
A13: PRP_PHAVU_11 | B13: 14 | C13: K | D13: Hydroxylysine:0.036 | E13: None
... A92: O236E_CONTE_54 | B92: 2 | C92: K | D92: Hydroxylysine:0.053 | E92: None
A93: >H2B1F_MOUSE_58
A94: H2B1F_MOUSE_58 | B94: 11 | C94: K | D94: Hydroxylysine:0.073 | E94: None
A95: >CLV3_ARATH_73
A96: >CXAT5_CONCE_56
A97: CXAT5_CONCE_56 | B97: 17 | C97: K | D97: Hydroxylysine:0.043 | E97: None
A98: >PCEP9_ARATH_51
A99: PCEP9_ARATH_51 | B99: 20 | C99: K | D99: Hydroxylysine:0.09 | E99: None
A100: PCEP9_ARATH_51 | B100: 21 | C100: K | D100: Hydroxylysine:0.087 | E100: None
A101: >CO1A1_CHICK_302
A102: >C1QB_HUMAN_77
A103: C1QB_HUMAN_77 | B103: 11 | C103: K | D103: Hydroxylysine:0.666 | E103: Hydroxylysine:0.666
A104: >CAFF_RIFPA_810
A105: CAFF_RIFPA_810 | B105: 11 | C105: K | D105: Hydroxylysine:0.506 | E105: Hydroxylysine:0.506
A106: >CO1A2_HUMAN_62
A107: >CO2A1_BOVIN_587
A108: >CO2A1_BOVIN_566
A109: CO2A1_BOVIN_566 | B109: 19 | C109: K | D109: Hydroxylysine:0.036 | E109: None
A110: >H14_HUMAN_46
A111: H14_HUMAN_46 | B111: 11 | C111: K | D111: Hydroxylysine:0.109 | E111: None
A112: H14_HUMAN_46 | B112: 17 | C112: K | D112: Hydroxylysine:0.127 | E112: None
A113: >HSY1_SOLLC_121
A114: HSY1_SOLLC_121 | B114: 13 | C114: K | D114: Hydroxylysine:0.221 | E114: None
A115: >CO1A1_BOVIN_1185
A116: >CO1A1_CHICK_392
A117: CO1A1_CHICK_392 | B117: 5 | C117: K | D117: Hydroxylysine:0.33 | E117: None
A118: >CM3E_CONPU_64
...

Sheet MusiteDeep-11
A1: ID | B1: Position | C1: Residue | D1: PTMscores | E1: Cutoff=0.5 | F1: Pred
A2: H14_HUMAN_97 | B2: 11 | C2: K | D2: Hydroxylysine:0.227 | E2: None | F2: =IF(E2="None",0,1) -> 0
A3: EFP_ECOLI_34 | B3: 11 | C3: K | D3: Hydroxylysine:0.053 | E3: None | F3: =IF(E3="None",0,1) -> 0
A4: C1QB_HUMAN_62 | B4: 11 | C4: K | D4: Hydroxylysine:0.713 | E4: Hydroxylysine:0.713 | F4: =IF(E4="None",0,1) -> 1
A5: CO6A3_HUMAN_2322 | B5: 11 | C5: K | D5: Hydroxylysine:0.694 | E5: Hydroxylysine:0.694 | F5: =IF(E5="None",0,1) -> 1
A6: CO2A1_BOVIN_542 | B6: 11 | C6: K | D6: Hydroxylysine:0.651 | E6: Hydroxylysine:0.651 | F6: =IF(E6="None",0,1) -> 1
A7: C1QT9_MOUSE_127 | B7: 11 | C7: K | D7: Hydroxylysine:0.499 | E7: None | F7: =IF(E7="None",0,1) -> 0
A8: H4_MOUSE_32 | B8: 11 | C8: K | D8: Hydroxylysine:0.116 | E8: None | F8: =IF(E8="None",0,1) -> 0
A9: CO1A2_BOVIN_175 | B9: 11 | C9: K | D9: Hydroxylysine:0.816 | E9: Hydroxylysine:0.816 | F9: =IF(E9="None",0,1) -> 1
A10: H2B1F_MOUSE_58 | B10: 11 | C10: K | D10: Hydroxylysine:0.073 | E10: None | F10: =IF(E10="None",0,1) -> 0
A11: C1QB_HUMAN_77 | B11: 11 | C11: K | D11: Hydroxylysine:0.666 | E11: Hydroxylysine:0.666 | F11: =IF(E11="None",0,1) -> 1
A12: CAFF_RIFPA_810 | B12: 11 | C12: K | D12: Hydroxylysine:0.506 | E12: Hydroxylysine:0.506 | F12: =IF(E12="None",0,1) -> 1
A13: H14_HUMAN_46 | B13: 11 | C13: K | D13: Hydroxylysine:0.109 | E13: None | F13: =IF(E13="None",0,1) -> 0
... A124: CO6A3_HUMAN_573 | B124: 11 | C124: K | D124: Hydroxylysine:0.053 | E124: None | F124: =IF(E124="None",0,1) -> 0
